<!--Ai generated-->
<mujoco model="k1_mocap">
  <compiler angle="radian" meshdir="meshes"/>

  <default>
    <motor ctrlrange="-1 1" ctrllimited="true"/>
    <joint actuatorfrclimited="true" type="hinge"/>
  </default>

  <asset>
    <mesh name="Trunk" file="Trunk.STL"/>
    <mesh name="Head_1" file="Head_1.STL"/>
    <mesh name="Head_2" file="Head_2.STL"/>
    <mesh name="Left_Arm_1" file="Left_Arm_1.STL"/>
    <mesh name="Left_Arm_2" file="Left_Arm_2.STL"/>
    <mesh name="Left_Arm_3" file="Left_Arm_3.STL"/>
    <mesh name="Left_Arm_4" file="Left_Arm_4.STL"/>
    <mesh name="Right_Arm_1" file="Right_Arm_1.STL"/>
    <mesh name="Right_Arm_2" file="Right_Arm_2.STL"/>
    <mesh name="Right_Arm_3" file="Right_Arm_3.STL"/>
    <mesh name="Right_Arm_4" file="Right_Arm_4.STL"/>
    <mesh name="Left_Hip_Pitch" file="Left_Hip_Pitch.STL"/>
    <mesh name="Left_Hip_Roll" file="Left_Hip_Roll.STL"/>
    <mesh name="Left_Hip_Yaw" file="Left_Hip_Yaw.STL"/>
    <mesh name="Left_Link_Long" file="Left_Link_Long.STL"/>
    <mesh name="Left_Shank" file="Left_Shank.STL"/>
    <mesh name="Left_Ankle_Cross" file="Left_Ankle_Cross.STL"/>
    <mesh name="Left_Foot" file="Left_Foot.STL"/>
    <mesh name="Right_Hip_Pitch" file="Right_Hip_Pitch.STL"/>
    <mesh name="Right_Hip_Roll" file="Right_Hip_Roll.STL"/>
    <mesh name="Right_Hip_Yaw" file="Right_Hip_Yaw.STL"/>
    <mesh name="Right_Link_Long" file="Right_Link_Long.STL"/>
    <mesh name="Right_Shank" file="Right_Shank.STL"/>
    <mesh name="Right_Ankle_Cross" file="Right_Ankle_Cross.STL"/>
    <mesh name="Right_Foot" file="Right_Foot.STL"/>
  </asset>

  <worldbody>
    <body name="Trunk" pos="0 0 1.0">
      <inertial pos="-0.0043392 -0.00065534 0.065686" mass="6.3921" diaginertia="0.096159 0.089512 0.020187"/>
      <freejoint name="Trunk"/>
      <geom type="mesh" contype="0" conaffinity="0" group="1" density="0" rgba="0.75 0.75 0.75 1" mesh="Trunk"/>
      <geom type="mesh" rgba="0.75 0.75 0.75 1" mesh="Trunk"/>
      <site name="imu_in_trunk" size="0.01" pos="0 0 0.1"/>
      <body name="imu_in_torso" pos="0 0 0.1"></body>
      
      <!-- Head -->
      <body name="Head_1" pos="0.0056 0 0.2149">
        <inertial pos="-0.00069503 -0.00038527 0.031688" mass="0.29729" diaginertia="0.000429 0.000421 0.000126"/>
        <joint name="AAHead_yaw" pos="0 0 0" axis="0 0 1" range="-1.0 1.0" actuatorfrcrange="-10 10"/>
        <geom type="mesh" contype="0" conaffinity="0" group="1" density="0" rgba="0.75 0.75 0.75 1" mesh="Head_1"/>
        <geom type="mesh" rgba="0.75 0.75 0.75 1" mesh="Head_1"/>
        <body name="Head_2" pos="0 0 0.057">
          <inertial pos="-0.00088616 0.00037926 0.019886" mass="0.26395" diaginertia="0.000226 0.000226 0.000113"/>
          <joint name="Head_pitch" pos="0 0 0" axis="0 1 0" range="-0.5 0.5" actuatorfrcrange="-10 10"/>
          <geom type="mesh" contype="0" conaffinity="0" group="1" density="0" rgba="0.75 0.75 0.75 1" mesh="Head_2"/>
          <geom type="mesh" rgba="0.75 0.75 0.75 1" mesh="Head_2"/>
          <body name="head_mocap" pos="0.0 0.0 0.05"></body>
        </body>
      </body>

      <!-- Left Arm -->
      <body name="Left_Arm_1" pos="-0.00815 0.186 0.1806">
        <inertial pos="0.00059693 0.072208 -0.01298" mass="0.84648" diaginertia="0.001538 0.001449 0.000713"/>
        <joint name="ALeft_Shoulder_Pitch" pos="0 0 0" axis="0 1 0" range="-3.14 3.14" actuatorfrcrange="-25 25"/>
        <geom type="mesh" contype="0" conaffinity="0" group="1" density="0" rgba="0.75 0.75 0.75 1" mesh="Left_Arm_1"/>
        <geom type="mesh" rgba="0.75 0.75 0.75 1" mesh="Left_Arm_1"/>
        <body name="Left_Arm_2" pos="0 0.0954 -0.01395">
          <inertial pos="-0.00041651 0.00035459 -0.086718" mass="0.71314" diaginertia="0.002041 0.002027 0.000309"/>
          <joint name="Left_Shoulder_Roll" pos="0 0 0" axis="1 0 0" range="-1.5 1.5" actuatorfrcrange="-25 25"/>
          <geom type="mesh" contype="0" conaffinity="0" group="1" density="0" rgba="0.75 0.75 0.75 1" mesh="Left_Arm_2"/>
          <geom type="mesh" rgba="0.75 0.75 0.75 1" mesh="Left_Arm_2"/>
          <body name="Left_Arm_3" pos="0 0 -0.153">
            <inertial pos="0.01077 0.00295 -0.072009" mass="0.734" diaginertia="0.00106187 0.00103217 0.000400661"/>
            <joint name="Left_Elbow_Pitch" pos="0 0 0" axis="0 1 0" range="-2.5 0.1" actuatorfrcrange="-25 25"/>
            <geom type="mesh" contype="0" conaffinity="0" group="1" density="0" rgba="0.75 0.75 0.75 1" mesh="Left_Arm_3"/>
            <geom type="mesh" rgba="0.75 0.75 0.75 1" mesh="Left_Arm_3"/>
            <body name="Left_Arm_4" pos="0.0158 0 -0.08052">
              <inertial pos="0.064956 0.004454 -0.010062" mass="0.6" diaginertia="0.000443035 0.000421612 0.000259353"/>
              <joint name="Left_Elbow_Yaw" pos="0 0 0" axis="0 0 1" range="-1.5 1.5" actuatorfrcrange="-15 15"/>
              <geom type="mesh" contype="0" conaffinity="0" group="1" density="0" rgba="0.75 0.75 0.75 1" mesh="Left_Arm_4"/>
              <geom type="mesh" rgba="0.75 0.75 0.75 1" mesh="Left_Arm_4"/>
              <body name="left_hand_end" pos="0.1 0.002 -0.01">
                <inertial pos="0.0 0.0 0.0" mass="0.1" diaginertia="0.001 0.001 0.001"/>
              </body>
            </body>
          </body>
        </body>
      </body>

      <!-- Right Arm -->
      <body name="Right_Arm_1" pos="-0.00815 -0.186 0.1806">
        <inertial pos="0.00059693 -0.072208 -0.01298" mass="0.84648" diaginertia="0.001538 0.001449 0.000713"/>
        <joint name="ARight_Shoulder_Pitch" pos="0 0 0" axis="0 1 0" range="-3.14 3.14" actuatorfrcrange="-25 25"/>
        <geom type="mesh" contype="0" conaffinity="0" group="1" density="0" rgba="0.75 0.75 0.75 1" mesh="Right_Arm_1"/>
        <geom type="mesh" rgba="0.75 0.75 0.75 1" mesh="Right_Arm_1"/>
        <body name="Right_Arm_2" pos="0 -0.0954 -0.01395">
          <inertial pos="-0.00041651 -0.00035459 -0.086718" mass="0.71314" diaginertia="0.002041 0.002027 0.000309"/>
          <joint name="Right_Shoulder_Roll" pos="0 0 0" axis="1 0 0" range="-1.5 1.5" actuatorfrcrange="-25 25"/>
          <geom type="mesh" contype="0" conaffinity="0" group="1" density="0" rgba="0.75 0.75 0.75 1" mesh="Right_Arm_2"/>
          <geom type="mesh" rgba="0.75 0.75 0.75 1" mesh="Right_Arm_2"/>
          <body name="Right_Arm_3" pos="0 0 -0.153">
            <inertial pos="0.01077 -0.00295 -0.072009" mass="0.734" diaginertia="0.00106187 0.00103217 0.000400661"/>
            <joint name="Right_Elbow_Pitch" pos="0 0 0" axis="0 1 0" range="-2.5 0.1" actuatorfrcrange="-25 25"/>
            <geom type="mesh" contype="0" conaffinity="0" group="1" density="0" rgba="0.75 0.75 0.75 1" mesh="Right_Arm_3"/>
            <geom type="mesh" rgba="0.75 0.75 0.75 1" mesh="Right_Arm_3"/>
            <body name="Right_Arm_4" pos="0.0158 0 -0.08052">
              <inertial pos="0.064956 -0.004454 -0.010062" mass="0.6" diaginertia="0.000443035 0.000421612 0.000259353"/>
              <joint name="Right_Elbow_Yaw" pos="0 0 0" axis="0 0 1" range="-1.5 1.5" actuatorfrcrange="-15 15"/>
              <geom type="mesh" contype="0" conaffinity="0" group="1" density="0" rgba="0.75 0.75 0.75 1" mesh="Right_Arm_4"/>
              <geom type="mesh" rgba="0.75 0.75 0.75 1" mesh="Right_Arm_4"/>
              <body name="right_hand_end" pos="0.1 -0.002 -0.01">
                <inertial pos="0.0 0.0 0.0" mass="0.1" diaginertia="0.001 0.001 0.001"/>
              </body>
            </body>
          </body>
        </body>
      </body>

      <!-- Left Leg -->
      <body name="Left_Hip_Pitch" pos="0 0.068 -0.14">
        <inertial pos="0.002741 0.047791 -0.02606" mass="1.35" diaginertia="0.001811 0.0014193 0.0012812"/>
        <joint name="Left_Hip_Pitch" pos="0 0 0" axis="0 1 0" range="-1.5 1.5" actuatorfrcrange="-100 100"/>
        <geom type="mesh" contype="0" conaffinity="0" group="1" density="0" rgba="0.75 0.75 0.75 1" mesh="Left_Hip_Pitch"/>
        <geom type="mesh" rgba="0.75 0.75 0.75 1" mesh="Left_Hip_Pitch"/>
        <body name="Left_Hip_Roll" pos="0 0.052 -0.0305">
          <inertial pos="0.029812 -0.001045 -0.087934" mass="1.52" diaginertia="0.0023773 0.0024123 0.0016595"/>
          <joint name="Left_Hip_Roll" pos="0 0 0" axis="1 0 0" range="-0.5 2.9" actuatorfrcrange="-100 100"/>
          <geom type="mesh" contype="0" conaffinity="0" group="1" density="0" rgba="0.75 0.75 0.75 1" mesh="Left_Hip_Roll"/>
          <geom type="mesh" rgba="0.75 0.75 0.75 1" mesh="Left_Hip_Roll"/>
          <body name="Left_Hip_Yaw" pos="0.025 0 -0.124">
            <inertial pos="-0.057709 0.010981 -0.15078" mass="1.702" diaginertia="0.00776166 0.00717575 0.00160139"/>
            <joint name="Left_Hip_Yaw" pos="0 0 0" axis="0 0 1" range="-2.7 2.7" actuatorfrcrange="-100 100"/>
            <geom type="mesh" contype="0" conaffinity="0" group="1" density="0" rgba="0.75 0.75 0.75 1" mesh="Left_Hip_Yaw"/>
            <geom type="mesh" rgba="0.75 0.75 0.75 1" mesh="Left_Hip_Yaw"/>
            <body name="Left_Link_Long" pos="-0.078 -0.002 -0.177">
              <inertial pos="0.005457 -0.003964 -0.12074" mass="1.932" diaginertia="0.011374 0.0112843 0.00146452"/>
              <joint name="Left_Knee_Pitch" pos="0 0 0" axis="0 1 0" range="-0.087 2.88" actuatorfrcrange="-100 100"/>
              <geom type="mesh" contype="0" conaffinity="0" group="1" density="0" rgba="0.75 0.75 0.75 1" mesh="Left_Link_Long"/>
              <geom type="mesh" rgba="0.75 0.75 0.75 1" mesh="Left_Link_Long"/>
              <body name="Left_Ankle_Cross" pos="0 0 -0.3">
                <inertial pos="-0.007269 0 0.011137" mass="0.074" diaginertia="1.89e-05 1.40805e-05 6.9195e-06"/>
                <joint name="Left_Ankle_Pitch" pos="0 0 0" axis="0 1 0" range="-0.87 0.52" actuatorfrcrange="-50 50"/>
                <geom type="mesh" contype="0" conaffinity="0" group="1" density="0" rgba="0.75 0.75 0.75 1" mesh="Left_Ankle_Cross"/>
                <geom type="mesh" rgba="0.75 0.75 0.75 1" mesh="Left_Ankle_Cross"/>
                <body name="left_foot_link" pos="0 0 0">
                  <inertial pos="0.026505 0 -0.016425" mass="0.608" diaginertia="0.00167218 0.0016161 0.000217621"/>
                  <joint name="Left_Ankle_Roll" pos="0 0 0" axis="1 0 0" range="-0.345 0.345" actuatorfrcrange="-50 50"/>
                  <geom type="mesh" contype="0" conaffinity="0" group="1" density="0" rgba="0.75 0.75 0.75 1" mesh="Left_Foot"/>
                  <geom type="mesh" rgba="0.75 0.75 0.75 1" mesh="Left_Foot"/>
                </body>
              </body>
            </body>
          </body>
        </body>
      </body>

      <!-- Right Leg -->
      <body name="Right_Hip_Pitch" pos="0 -0.068 -0.14">
        <inertial pos="0.002741 -0.047791 -0.02606" mass="1.35" diaginertia="0.001811 0.0014193 0.0012812"/>
        <joint name="Right_Hip_Pitch" pos="0 0 0" axis="0 1 0" range="-1.5 1.5" actuatorfrcrange="-100 100"/>
        <geom type="mesh" contype="0" conaffinity="0" group="1" density="0" rgba="0.75 0.75 0.75 1" mesh="Right_Hip_Pitch"/>
        <geom type="mesh" rgba="0.75 0.75 0.75 1" mesh="Right_Hip_Pitch"/>
        <body name="Right_Hip_Roll" pos="0 -0.052 -0.0305">
          <inertial pos="0.029812 0.001045 -0.087934" mass="1.52" diaginertia="0.0023773 0.0024123 0.0016595"/>
          <joint name="Right_Hip_Roll" pos="0 0 0" axis="1 0 0" range="-2.9 0.5" actuatorfrcrange="-100 100"/>
          <geom type="mesh" contype="0" conaffinity="0" group="1" density="0" rgba="0.75 0.75 0.75 1" mesh="Right_Hip_Roll"/>
          <geom type="mesh" rgba="0.75 0.75 0.75 1" mesh="Right_Hip_Roll"/>
          <body name="Right_Hip_Yaw" pos="0.025 0 -0.124">
            <inertial pos="-0.057709 -0.010981 -0.15078" mass="1.702" diaginertia="0.00776166 0.00717575 0.00160139"/>
            <joint name="Right_Hip_Yaw" pos="0 0 0" axis="0 0 1" range="-2.7 2.7" actuatorfrcrange="-100 100"/>
            <geom type="mesh" contype="0" conaffinity="0" group="1" density="0" rgba="0.75 0.75 0.75 1" mesh="Right_Hip_Yaw"/>
            <geom type="mesh" rgba="0.75 0.75 0.75 1" mesh="Right_Hip_Yaw"/>
            <body name="Right_Link_Long" pos="-0.078 0.002 -0.177">
              <inertial pos="0.005457 0.003964 -0.12074" mass="1.932" diaginertia="0.011374 0.0112843 0.00146452"/>
              <joint name="Right_Knee_Pitch" pos="0 0 0" axis="0 1 0" range="-0.087 2.88" actuatorfrcrange="-100 100"/>
              <geom type="mesh" contype="0" conaffinity="0" group="1" density="0" rgba="0.75 0.75 0.75 1" mesh="Right_Link_Long"/>
              <geom type="mesh" rgba="0.75 0.75 0.75 1" mesh="Right_Link_Long"/>
              <body name="Right_Ankle_Cross" pos="0 0 -0.3">
                <inertial pos="-0.007269 0 0.011137" mass="0.074" diaginertia="1.89e-05 1.40805e-05 6.9195e-06"/>
                <joint name="Right_Ankle_Pitch" pos="0 0 0" axis="0 1 0" range="-0.87 0.52" actuatorfrcrange="-50 50"/>
                <geom type="mesh" contype="0" conaffinity="0" group="1" density="0" rgba="0.75 0.75 0.75 1" mesh="Right_Ankle_Cross"/>
                <geom type="mesh" rgba="0.75 0.75 0.75 1" mesh="Right_Ankle_Cross"/>
                <body name="right_foot_link" pos="0 0 0">
                  <inertial pos="0.026505 0 -0.016425" mass="0.608" diaginertia="0.00167218 0.0016161 0.000217621"/>
                  <joint name="Right_Ankle_Roll" pos="0 0 0" axis="1 0 0" range="-0.345 0.345" actuatorfrcrange="-50 50"/>
                  <geom type="mesh" contype="0" conaffinity="0" group="1" density="0" rgba="0.75 0.75 0.75 1" mesh="Right_Foot"/>
                  <geom type="mesh" rgba="0.75 0.75 0.75 1" mesh="Right_Foot"/>
                </body>
              </body>
            </body>
          </body>
        </body>
      </body>
    </body>
  </worldbody>

  <actuator>
    <motor name="AAHead_yaw" joint="AAHead_yaw"/>
    <motor name="Head_pitch" joint="Head_pitch"/>
    <motor name="ALeft_Shoulder_Pitch" joint="ALeft_Shoulder_Pitch"/>
    <motor name="Left_Shoulder_Roll" joint="Left_Shoulder_Roll"/>
    <motor name="Left_Elbow_Pitch" joint="Left_Elbow_Pitch"/>
    <motor name="Left_Elbow_Yaw" joint="Left_Elbow_Yaw"/>
    <motor name="ARight_Shoulder_Pitch" joint="ARight_Shoulder_Pitch"/>
    <motor name="Right_Shoulder_Roll" joint="Right_Shoulder_Roll"/>
    <motor name="Right_Elbow_Pitch" joint="Right_Elbow_Pitch"/>
    <motor name="Right_Elbow_Yaw" joint="Right_Elbow_Yaw"/>
    <motor name="Left_Hip_Pitch" joint="Left_Hip_Pitch"/>
    <motor name="Left_Hip_Roll" joint="Left_Hip_Roll"/>
    <motor name="Left_Hip_Yaw" joint="Left_Hip_Yaw"/>
    <motor name="Left_Knee_Pitch" joint="Left_Knee_Pitch"/>
    <motor name="Left_Ankle_Pitch" joint="Left_Ankle_Pitch"/>
    <motor name="Left_Ankle_Roll" joint="Left_Ankle_Roll"/>
    <motor name="Right_Hip_Pitch" joint="Right_Hip_Pitch"/>
    <motor name="Right_Hip_Roll" joint="Right_Hip_Roll"/>
    <motor name="Right_Hip_Yaw" joint="Right_Hip_Yaw"/>
    <motor name="Right_Knee_Pitch" joint="Right_Knee_Pitch"/>
    <motor name="Right_Ankle_Pitch" joint="Right_Ankle_Pitch"/>
    <motor name="Right_Ankle_Roll" joint="Right_Ankle_Roll"/>
  </actuator>

  <sensor>
    <gyro name="imu-trunk-angular-velocity" site="imu_in_trunk" noise="5e-4" cutoff="34.9"/>
    <accelerometer name="imu-trunk-linear-acceleration" site="imu_in_trunk" noise="1e-2" cutoff="157"/>
  </sensor>
</mujoco>